2023-06-03 00:48:53,819 ERROR: Exception on /explore [GET] in [/home/shtaket/dev/flask/microblog/venv/lib/python3.10/site-packages/flask/app.py:1414]
Traceback (most recent call last):
  File "/home/shtaket/dev/flask/microblog/venv/lib/python3.10/site-packages/flask/app.py", line 2190, in wsgi_app
    response = self.full_dispatch_request()
  File "/home/shtaket/dev/flask/microblog/venv/lib/python3.10/site-packages/flask/app.py", line 1486, in full_dispatch_request
    rv = self.handle_user_exception(e)
  File "/home/shtaket/dev/flask/microblog/venv/lib/python3.10/site-packages/flask/app.py", line 1484, in full_dispatch_request
    rv = self.dispatch_request()
  File "/home/shtaket/dev/flask/microblog/venv/lib/python3.10/site-packages/flask/app.py", line 1469, in dispatch_request
    return self.ensure_sync(self.view_functions[rule.endpoint])(**view_args)
  File "/home/shtaket/dev/flask/microblog/app/routes.py", line 168, in explore
    app.config['POSTS_PER_PAGE'],
KeyError: 'POSTS_PER_PAGE'
2023-06-03 00:49:30,430 INFO: Microblog startup in [/home/shtaket/dev/flask/microblog/app/__init__.py:32]
2023-06-03 00:49:32,514 ERROR: Exception on /explore [GET] in [/home/shtaket/dev/flask/microblog/venv/lib/python3.10/site-packages/flask/app.py:1414]
Traceback (most recent call last):
  File "/home/shtaket/dev/flask/microblog/venv/lib/python3.10/site-packages/flask/app.py", line 2190, in wsgi_app
    response = self.full_dispatch_request()
  File "/home/shtaket/dev/flask/microblog/venv/lib/python3.10/site-packages/flask/app.py", line 1486, in full_dispatch_request
    rv = self.handle_user_exception(e)
  File "/home/shtaket/dev/flask/microblog/venv/lib/python3.10/site-packages/flask/app.py", line 1484, in full_dispatch_request
    rv = self.dispatch_request()
  File "/home/shtaket/dev/flask/microblog/venv/lib/python3.10/site-packages/flask/app.py", line 1469, in dispatch_request
    return self.ensure_sync(self.view_functions[rule.endpoint])(**view_args)
  File "/home/shtaket/dev/flask/microblog/app/routes.py", line 168, in explore
    app.CONFIG['POSTS_PER_PAGE'],
AttributeError: 'Flask' object has no attribute 'CONFIG'
2023-06-03 00:49:33,662 ERROR: Exception on /explore [GET] in [/home/shtaket/dev/flask/microblog/venv/lib/python3.10/site-packages/flask/app.py:1414]
Traceback (most recent call last):
  File "/home/shtaket/dev/flask/microblog/venv/lib/python3.10/site-packages/flask/app.py", line 2190, in wsgi_app
    response = self.full_dispatch_request()
  File "/home/shtaket/dev/flask/microblog/venv/lib/python3.10/site-packages/flask/app.py", line 1486, in full_dispatch_request
    rv = self.handle_user_exception(e)
  File "/home/shtaket/dev/flask/microblog/venv/lib/python3.10/site-packages/flask/app.py", line 1484, in full_dispatch_request
    rv = self.dispatch_request()
  File "/home/shtaket/dev/flask/microblog/venv/lib/python3.10/site-packages/flask/app.py", line 1469, in dispatch_request
    return self.ensure_sync(self.view_functions[rule.endpoint])(**view_args)
  File "/home/shtaket/dev/flask/microblog/app/routes.py", line 168, in explore
    app.CONFIG['POSTS_PER_PAGE'],
AttributeError: 'Flask' object has no attribute 'CONFIG'
2023-06-03 00:49:34,396 ERROR: Exception on /explore [GET] in [/home/shtaket/dev/flask/microblog/venv/lib/python3.10/site-packages/flask/app.py:1414]
Traceback (most recent call last):
  File "/home/shtaket/dev/flask/microblog/venv/lib/python3.10/site-packages/flask/app.py", line 2190, in wsgi_app
    response = self.full_dispatch_request()
  File "/home/shtaket/dev/flask/microblog/venv/lib/python3.10/site-packages/flask/app.py", line 1486, in full_dispatch_request
    rv = self.handle_user_exception(e)
  File "/home/shtaket/dev/flask/microblog/venv/lib/python3.10/site-packages/flask/app.py", line 1484, in full_dispatch_request
    rv = self.dispatch_request()
  File "/home/shtaket/dev/flask/microblog/venv/lib/python3.10/site-packages/flask/app.py", line 1469, in dispatch_request
    return self.ensure_sync(self.view_functions[rule.endpoint])(**view_args)
  File "/home/shtaket/dev/flask/microblog/app/routes.py", line 168, in explore
    app.CONFIG['POSTS_PER_PAGE'],
AttributeError: 'Flask' object has no attribute 'CONFIG'
2023-06-03 00:50:08,612 INFO: Microblog startup in [/home/shtaket/dev/flask/microblog/app/__init__.py:32]
2023-06-03 00:50:12,105 ERROR: Exception on /explore [GET] in [/home/shtaket/dev/flask/microblog/venv/lib/python3.10/site-packages/flask/app.py:1414]
Traceback (most recent call last):
  File "/home/shtaket/dev/flask/microblog/venv/lib/python3.10/site-packages/flask/app.py", line 2190, in wsgi_app
    response = self.full_dispatch_request()
  File "/home/shtaket/dev/flask/microblog/venv/lib/python3.10/site-packages/flask/app.py", line 1486, in full_dispatch_request
    rv = self.handle_user_exception(e)
  File "/home/shtaket/dev/flask/microblog/venv/lib/python3.10/site-packages/flask/app.py", line 1484, in full_dispatch_request
    rv = self.dispatch_request()
  File "/home/shtaket/dev/flask/microblog/venv/lib/python3.10/site-packages/flask/app.py", line 1469, in dispatch_request
    return self.ensure_sync(self.view_functions[rule.endpoint])(**view_args)
  File "/home/shtaket/dev/flask/microblog/app/routes.py", line 166, in explore
    posts = Post.query.order_by(Post.timestamp.desc()).paginate(
TypeError: Query.paginate() takes 1 positional argument but 4 were given
2023-06-03 00:50:12,773 ERROR: Exception on /explore [GET] in [/home/shtaket/dev/flask/microblog/venv/lib/python3.10/site-packages/flask/app.py:1414]
Traceback (most recent call last):
  File "/home/shtaket/dev/flask/microblog/venv/lib/python3.10/site-packages/flask/app.py", line 2190, in wsgi_app
    response = self.full_dispatch_request()
  File "/home/shtaket/dev/flask/microblog/venv/lib/python3.10/site-packages/flask/app.py", line 1486, in full_dispatch_request
    rv = self.handle_user_exception(e)
  File "/home/shtaket/dev/flask/microblog/venv/lib/python3.10/site-packages/flask/app.py", line 1484, in full_dispatch_request
    rv = self.dispatch_request()
  File "/home/shtaket/dev/flask/microblog/venv/lib/python3.10/site-packages/flask/app.py", line 1469, in dispatch_request
    return self.ensure_sync(self.view_functions[rule.endpoint])(**view_args)
  File "/home/shtaket/dev/flask/microblog/app/routes.py", line 166, in explore
    posts = Post.query.order_by(Post.timestamp.desc()).paginate(
TypeError: Query.paginate() takes 1 positional argument but 4 were given
2023-06-03 00:51:14,183 ERROR: Exception on /explore [GET] in [/home/shtaket/dev/flask/microblog/venv/lib/python3.10/site-packages/flask/app.py:1414]
Traceback (most recent call last):
  File "/home/shtaket/dev/flask/microblog/venv/lib/python3.10/site-packages/flask/app.py", line 2190, in wsgi_app
    response = self.full_dispatch_request()
  File "/home/shtaket/dev/flask/microblog/venv/lib/python3.10/site-packages/flask/app.py", line 1486, in full_dispatch_request
    rv = self.handle_user_exception(e)
  File "/home/shtaket/dev/flask/microblog/venv/lib/python3.10/site-packages/flask/app.py", line 1484, in full_dispatch_request
    rv = self.dispatch_request()
  File "/home/shtaket/dev/flask/microblog/venv/lib/python3.10/site-packages/flask/app.py", line 1469, in dispatch_request
    return self.ensure_sync(self.view_functions[rule.endpoint])(**view_args)
  File "/home/shtaket/dev/flask/microblog/app/routes.py", line 166, in explore
    posts = Post.query.order_by(Post.timestamp.desc()).paginate(
TypeError: Query.paginate() takes 1 positional argument but 4 were given
2023-06-03 00:52:40,811 INFO: Microblog startup in [/home/shtaket/dev/flask/microblog/app/__init__.py:32]
2023-06-03 01:02:24,957 INFO: Microblog startup in [/home/shtaket/dev/flask/microblog/app/__init__.py:32]
2023-06-03 01:03:28,577 INFO: Microblog startup in [/home/shtaket/dev/flask/microblog/app/__init__.py:32]
